Workbook

Sheet personal_labor_income_taxes
A1: Date | B1: Total Gross Income Tax Division | C1: Total refunds from the Income Tax Department | D1: Total Income Tax Division Net | E1: Deductions and the capital market | F1: Deduction from salary | G1: Independents advances | H1: Self-employed tax differences | I1: Independent Cancellations | J1: self employed returns | K1: Capital Gains Tax Refunds | L1: VAT Financial Institutions (Salary) | M1: Non-profit institution tax
A2: 35065 | B2: =[1]ישיר!B6 -> 4774987 | C2: =-1*[1]ישיר!$C6 -> -680754 | D2: =personal_labor_income_taxes!B2+C2 -> 4094233 | E2: =[1]ישיר!$F6 -> 2775423 | F2: =[1]ישיר!$V6 -> 2183611 | G2: =[1]ישיר!$H6 -> 23709 | H2: =[1]ישיר!$I6 -> 600103 | I2: =-1*[1]ישיר!$J6 -> -4331 | J2: =-1*[1]ישיר!$AG6 -> -112555 | K2: =-1*[1]ישיר!$AK6 -> -16848 | L2: =-1*[1]ישיר!$Z6 -> -60689 | M2: =[1]ישיר!$Y6 -> 196775
A3: 35096 | B3: =[1]ישיר!B7 -> 4874883 | C3: =-1*[1]ישיר!$C7 -> -436582 | D3: =personal_labor_income_taxes!B3+C3 -> 4438301 | E3: =[1]ישיר!$F7 -> 2717365 | F3: =[1]ישיר!$V7 -> 2040219 | G3: =[1]ישיר!$H7 -> 326348 | H3: =[1]ישיר!$I7 -> 202116 | I3: =-1*[1]ישיר!$J7 -> -6226 | J3: =-1*[1]ישיר!$AG7 -> -83118 | K3: =-1*[1]ישיר!$AK7 -> -5091 | L3: =-1*[1]ישיר!$Z7 -> -61703 | M3: =[1]ישיר!$Y7 -> 258045
A4: 35125 | B4: =[1]ישיר!B8 -> 4747457 | C4: =-1*[1]ישיר!$C8 -> -337940 | D4: =personal_labor_income_taxes!B4+C4 -> 4409517 | E4: =[1]ישיר!$F8 -> 2903470 | F4: =[1]ישיר!$V8 -> 2265911 | G4: =[1]ישיר!$H8 -> 437301 | H4: =[1]ישיר!$I8 -> 119197 | I4: =-1*[1]ישיר!$J8 -> -2159 | J4: =-1*[1]ישיר!$AG8 -> -69766 | K4: =-1*[1]ישיר!$AK8 -> -11221 | L4: =-1*[1]ישיר!$Z8 -> -59295 | M4: =[1]ישיר!$Y8 -> 236928
A5: 35156 | B5: =[1]ישיר!B9 -> 4344510 | C5: =-1*[1]ישיר!$C9 -> -328559 | D5: =personal_labor_income_taxes!B5+C5 -> 4015951 | E5: =[1]ישיר!$F9 -> 2703780 | F5: =[1]ישיר!$V9 -> 2075698 | G5: =[1]ישיר!$H9 -> 295287 | H5: =[1]ישיר!$I9 -> 102835 | I5: =-1*[1]ישיר!$J9 -> -3505 | J5: =-1*[1]ישיר!$AG9 -> -42851 | K5: =-1*[1]ישיר!$AK9 -> -7480 | L5: =-1*[1]ישיר!$Z9 -> -87516 | M5: =[1]ישיר!$Y9 -> 231896
A6: 35186 | B6: =[1]ישיר!B10 -> 4685954 | C6: =-1*[1]ישיר!$C10 -> -297485 | D6: =personal_labor_income_taxes!B6+C6 -> 4388469 | E6: =[1]ישיר!$F10 -> 2924295 | F6: =[1]ישיר!$V10 -> 2259705 | G6: =[1]ישיר!$H10 -> 432090 | H6: =[1]ישיר!$I10 -> 110420 | I6: =-1*[1]ישיר!$J10 -> -4939 | J6: =-1*[1]ישיר!$AG10 -> -141592 | K6: =-1*[1]ישיר!$AK10 -> -4311 | L6: =-1*[1]ישיר!$Z10 -> -55916 | M6: =[1]ישיר!$Y10 -> 259031
A7: 35217 | B7: =[1]ישיר!B11 -> 4219188 | C7: =-1*[1]ישיר!$C11 -> -309144 | D7: =personal_labor_income_taxes!B7+C7 -> 3910044 | E7: =[1]ישיר!$F11 -> 2543930 | F7: =[1]ישיר!$V11 -> 1908199 | G7: =[1]ישיר!$H11 -> 323198 | H7: =[1]ישיר!$I11 -> 153808 | I7: =-1*[1]ישיר!$J11 -> -4353 | J7: =-1*[1]ישיר!$AG11 -> -197849 | K7: =-1*[1]ישיר!$AK11 -> -10043 | L7: =-1*[1]ישיר!$Z11 -> -53518 | M7: =[1]ישיר!$Y11 -> 262471
A8: 35247 | B8: =[1]ישיר!B12 -> 5275390 | C8: =-1*[1]ישיר!$C12 -> -471700 | D8: =personal_labor_income_taxes!B8+C8 -> 4803690 | E8: =[1]ישיר!$F12 -> 3308040 | F8: =[1]ישיר!$V12 -> 2591462 | G8: =[1]ישיר!$H12 -> 474844 | H8: =[1]ישיר!$I12 -> 116932 | I8: =-1*[1]ישיר!$J12 -> -3942 | J8: =-1*[1]ישיר!$AG12 -> -234310 | K8: =-1*[1]ישיר!$AK12 -> -3902 | L8: =-1*[1]ישיר!$Z12 -> -45899 | M8: =[1]ישיר!$Y12 -> 308877
A9: 35278 | B9: =[1]ישיר!B13 -> 4620456 | C9: =-1*[1]ישיר!$C13 -> -509112 | D9: =personal_labor_income_taxes!B9+C9 -> 4111344 | E9: =[1]ישיר!$F13 -> 2987933 | F9: =[1]ישיר!$V13 -> 2279710 | G9: =[1]ישיר!$H13 -> 354186 | H9: =[1]ישיר!$I13 -> 123234 | I9: =-1*[1]ישיר!$J13 -> -5878 | J9: =-1*[1]ישיר!$AG13 -> -255882 | K9: =-1*[1]ישיר!$AK13 -> -4986 | L9: =-1*[1]ישיר!$Z13 -> -53064 | M9: =[1]ישיר!$Y13 -> 298453
A10: 35309 | B10: =[1]ישיר!B14 -> 4990967 | C10: =-1*[1]ישיר!$C14 -> -372648 | D10: =personal_labor_income_taxes!B10+C10 -> 4618319 | E10: =[1]ישיר!$F14 -> 3198954 | F10: =[1]ישיר!$V14 -> 2490302 | G10: =[1]ישיר!$H14 -> 501668 | H10: =[1]ישיר!$I14 -> 125946 | I10: =-1*[1]ישיר!$J14 -> -2821 | J10: =-1*[1]ישיר!$AG14 -> -161668 | K10: =-1*[1]ישיר!$AK14 -> -8643 | L10: =-1*[1]ישיר!$Z14 -> -53802 | M10: =[1]ישיר!$Y14 -> 282085
A11: 35339 | B11: =[1]ישיר!B15 -> 4383491 | C11: =-1*[1]ישיר!$C15 -> -438401 | D11: =personal_labor_income_taxes!B11+C11 -> 3945090 | E11: =[1]ישיר!$F15 -> 2735431 | F11: =[1]ישיר!$V15 -> 2076888 | G11: =[1]ישיר!$H15 -> 325279 | H11: =[1]ישיר!$I15 -> 119995 | I11: =-1*[1]ישיר!$J15 -> -7402 | J11: =-1*[1]ישיר!$AG15 -> -161244 | K11: =-1*[1]ישיר!$AK15 -> -4429 | L11: =-1*[1]ישיר!$Z15 -> -51547 | M11: =[1]ישיר!$Y15 -> 272624
A12: 35370 | B12: =[1]ישיר!B16 -> 5032923 | C12: =-1*[1]ישיר!$C16 -> -519094 | D12: =personal_labor_income_taxes!B12+C12 -> 4513829 | E12: =[1]ישיר!$F16 -> 3072490 | F12: =[1]ישיר!$V16 -> 2374642 | G12: =[1]ישיר!$H16 -> 513250 | H12: =[1]ישיר!$I16 -> 144010 | I12: =-1*[1]ישיר!$J16 -> -2877 | J12: =-1*[1]ישיר!$AG16 -> -134578 | K12: =-1*[1]ישיר!$AK16 -> -3593 | L12: =-1*[1]ישיר!$Z16 -> -50385 | M12: =[1]ישיר!$Y16 -> 272018
A13: 35400 | B13: =[1]ישיר!B17 -> 4418478 | C13: =-1*[1]ישיר!$C17 -> -668837 | D13: =personal_labor_income_taxes!B13+C13 -> 3749641 | E13: =[1]ישיר!$F17 -> 2833585 | F13: =[1]ישיר!$V17 -> 2148921 | G13: =[1]ישיר!$H17 -> 314112 | H13: =[1]ישיר!$I17 -> 137124 | I13: =-1*[1]ישיר!$J17 -> -5140 | J13: =-1*[1]ישיר!$AG17 -> -115060 | K13: =-1*[1]ישיר!$AK17 -> -6468 | L13: =-1*[1]ישיר!$Z17 -> -48610 | M13: =[1]ישיר!$Y17 -> 284343
... A365: 46113 | B365: =[1]ישיר!B369 -> 31122821 | C365: =-1*[1]ישיר!$C369 -> -1598434 | D365: =personal_labor_income_taxes!B365+C365 -> 29524387 | E365: =[1]ישיר!$F369 -> 19391474 | F365: =[1]ישיר!$V369 -> 14637002 | G365: =[1]ישיר!$H369 -> 1281896 | H365: =[1]ישיר!$I369 -> 1084637 | I365: =-1*[1]ישיר!$J369 -> -11235 | J365: =-1*[1]ישיר!$AG369 -> -471351 | K365: =-1*[1]ישיר!$AK369 -> -46488 | L365: =-1*[1]ישיר!$Z369 -> -165937 | M365: =[1]ישיר!$Y369 -> 1192012
A366: 46143

Sheet corporate_business_tax
A1: Date | B1: Companies advances | C1: tax differential companies | D1: Cancellation companies | E1: Income tax for self-employed individuals and companies (advances and deductions) | F1: Companies returns | G1: excess expenses | H1: Bonds and dividends | I1: Cancellations Deductions | J1: Goods and services
A2: 35065 | B2: ='[1]ישיר מתוקן'!$K6 -> 26460 | C2: ='[1]ישיר מתוקן'!$L6 -> 936207 | D2: =-1*'[1]ישיר מתוקן'!$M6 -> -5875 | E2: ='[1]ישיר מתוקן'!$E6 -> 1576274 | F2: =-1*'[1]ישיר מתוקן'!$AF6 -> -541940 | G2: ='[1]ישיר מתוקן'!$AA6 -> 70820 | H2: ='[1]ישיר מתוקן'!$AD6 -> 13941 | I2: =-1*'[1]ישיר מתוקן'!$AE6 -> -33284 | J2: ='[1]ישיר מתוקן'!$W6 -> 224948
A3: 35096 | B3: ='[1]ישיר מתוקן'!$K7 -> 723337 | C3: ='[1]ישיר מתוקן'!$L7 -> 688298 | D3: =-1*'[1]ישיר מתוקן'!$M7 -> -217032 | E3: ='[1]ישיר מתוקן'!$E7 -> 1716840 | F3: =-1*'[1]ישיר מתוקן'!$AF7 -> -342359 | G3: ='[1]ישיר מתוקן'!$AA7 -> 41306 | H3: ='[1]ישיר מתוקן'!$AD7 -> 17812 | I3: =-1*'[1]ישיר מתוקן'!$AE7 -> -34953 | J3: ='[1]ישיר מתוקן'!$W7 -> 191896
A4: 35125 | B4: ='[1]ישיר מתוקן'!$K8 -> 730004 | C4: ='[1]ישיר מתוקן'!$L8 -> 205284 | D4: =-1*'[1]ישיר מתוקן'!$M8 -> -2119 | E4: ='[1]ישיר מתוקן'!$E8 -> 1487508 | F4: =-1*'[1]ישיר מתוקן'!$AF8 -> -246389 | G4: ='[1]ישיר מתוקן'!$AA8 -> 44452 | H4: ='[1]ישיר מתוקן'!$AD8 -> 20135 | I4: =-1*'[1]ישיר מתוקן'!$AE8 -> -19980 | J4: ='[1]ישיר מתוקן'!$W8 -> 194206
A5: 35156 | B5: ='[1]ישיר מתוקן'!$K9 -> 757856 | C5: ='[1]ישיר מתוקן'!$L9 -> 187120 | D5: =-1*'[1]ישיר מתוקן'!$M9 -> -4237 | E5: ='[1]ישיר מתוקן'!$E9 -> 1335357 | F5: =-1*'[1]ישיר מתוקן'!$AF9 -> -272817 | G5: ='[1]ישיר מתוקן'!$AA9 -> 42520 | H5: ='[1]ישיר מתוקן'!$AD9 -> 13139 | I5: =-1*'[1]ישיר מתוקן'!$AE9 -> -20970 | J5: ='[1]ישיר מתוקן'!$W9 -> 172525
A6: 35186 | B6: ='[1]ישיר מתוקן'!$K10 -> 700649 | C6: ='[1]ישיר מתוקן'!$L10 -> 202258 | D6: =-1*'[1]ישיר מתוקן'!$M10 -> -2612 | E6: ='[1]ישיר מתוקן'!$E10 -> 1437865 | F6: =-1*'[1]ישיר מתוקן'!$AF10 -> -145617 | G6: ='[1]ישיר מתוקן'!$AA10 -> 47858 | H6: ='[1]ישיר מתוקן'!$AD10 -> 28679 | I6: =-1*'[1]ישיר מתוקן'!$AE10 -> -18950 | J6: ='[1]ישיר מתוקן'!$W10 -> 188355
A7: 35217 | B7: ='[1]ישיר מתוקן'!$K11 -> 761807 | C7: ='[1]ישיר מתוקן'!$L11 -> 132306 | D7: =-1*'[1]ישיר מתוקן'!$M11 -> -4398 | E7: ='[1]ישיר מתוקן'!$E11 -> 1362366 | F7: =-1*'[1]ישיר מתוקן'!$AF11 -> -92471 | G7: ='[1]ישיר מתוקן'!$AA11 -> 42387 | H7: ='[1]ישיר מתוקן'!$AD11 -> 15510 | I7: =-1*'[1]ישיר מתוקן'!$AE11 -> -16134 | J7: ='[1]ישיר מתוקן'!$W11 -> 170777
A8: 35247 | B8: ='[1]ישיר מתוקן'!$K12 -> 758705 | C8: ='[1]ישיר מתוקן'!$L12 -> 322943 | D8: =-1*'[1]ישיר מתוקן'!$M12 -> -4800 | E8: ='[1]ישיר מתוקן'!$E12 -> 1664682 | F8: =-1*'[1]ישיר מתוקן'!$AF12 -> -224900 | G8: ='[1]ישיר מתוקן'!$AA12 -> 47745 | H8: ='[1]ישיר מתוקן'!$AD12 -> 25125 | I8: =-1*'[1]ישיר מתוקן'!$AE12 -> -33700 | J8: ='[1]ישיר מתוקן'!$W12 -> 204018
A9: 35278 | B9: ='[1]ישיר מתוקן'!$K13 -> 744798 | C9: ='[1]ישיר מתוקן'!$L13 -> 134586 | D9: =-1*'[1]ישיר מתוקן'!$M13 -> -4613 | E9: ='[1]ישיר מתוקן'!$E13 -> 1346314 | F9: =-1*'[1]ישיר מתוקן'!$AF13 -> -240129 | G9: ='[1]ישיר מתוקן'!$AA13 -> 49167 | H9: ='[1]ישיר מתוקן'!$AD13 -> 28107 | I9: =-1*'[1]ישיר מתוקן'!$AE13 -> -48232 | J9: ='[1]ישיר מתוקן'!$W13 -> 206173
A10: 35309 | B10: ='[1]ישיר מתוקן'!$K14 -> 796276 | C10: ='[1]ישיר מתוקן'!$L14 -> 143980 | D10: =-1*'[1]ישיר מתוקן'!$M14 -> -1683 | E10: ='[1]ישיר מתוקן'!$E14 -> 1563365 | F10: =-1*'[1]ישיר מתוקן'!$AF14 -> -190784 | G10: ='[1]ישיר מתוקן'!$AA14 -> 53036 | H10: ='[1]ישיר מתוקן'!$AD14 -> 11375 | I10: =-1*'[1]ישיר מתוקן'!$AE14 -> -26444 | J10: ='[1]ישיר מתוקן'!$W14 -> 221720
A11: 35339 | B11: ='[1]ישיר מתוקן'!$K15 -> 821045 | C11: ='[1]ישיר מתוקן'!$L15 -> 179332 | D11: =-1*'[1]ישיר מתוקן'!$M15 -> -2749 | E11: ='[1]ישיר מתוקן'!$E15 -> 1435500 | F11: =-1*'[1]ישיר מתוקן'!$AF15 -> -263434 | G11: ='[1]ישיר מתוקן'!$AA15 -> 50828 | H11: ='[1]ישיר מתוקן'!$AD15 -> 26147 | I11: =-1*'[1]ישיר מתוקן'!$AE15 -> -39537 | J11: ='[1]ישיר מתוקן'!$W15 -> 192588
A12: 35370 | B12: ='[1]ישיר מתוקן'!$K16 -> 920990 | C12: ='[1]ישיר מתוקן'!$L16 -> 151525 | D12: =-1*'[1]ישיר מתוקן'!$M16 -> -3392 | E12: ='[1]ישיר מתוקן'!$E16 -> 1723506 | F12: =-1*'[1]ישיר מתוקן'!$AF16 -> -368163 | G12: ='[1]ישיר מתוקן'!$AA16 -> 55482 | H12: ='[1]ישיר מתוקן'!$AD16 -> 10748 | I12: =-1*'[1]ישיר מתוקן'!$AE16 -> -17232 | J12: ='[1]ישיר מתוקן'!$W16 -> 217304
A13: 35400 | B13: ='[1]ישיר מתוקן'!$K17 -> 624866 | C13: ='[1]ישיר מתוקן'!$L17 -> 211001 | D13: =-1*'[1]ישיר מתוקן'!$M17 -> -3023 | E13: ='[1]ישיר מתוקן'!$E17 -> 1278939 | F13: =-1*'[1]ישיר מתוקן'!$AF17 -> -537046 | G13: ='[1]ישיר מתוקן'!$AA17 -> 51927 | H13: ='[1]ישיר מתוקן'!$AD17 -> 19501 | I13: =-1*'[1]ישיר מתוקן'!$AE17 -> -14188 | J13: ='[1]ישיר מתוקן'!$W17 -> 183138
... A365: 46113 | B365: ='[1]ישיר מתוקן'!$K369 -> 6448873 | C365: ='[1]ישיר מתוקן'!$L369 -> 1595501 | D365: =-1*'[1]ישיר מתוקן'!$M369 -> -8053 | E365: ='[1]ישיר מתוקן'!$E369 -> 10389619 | F365: =-1*'[1]ישיר מתוקן'!$AF369 -> -978856 | G365: ='[1]ישיר מתוקן'!$AA369 -> 73354 | H365: ='[1]ישיר מתוקן'!$AD369 -> 601545 | I365: =-1*'[1]ישיר מתוקן'!$AE369 -> -17981 | J365: ='[1]ישיר מתוקן'!$W369 -> 1041882

Sheet consumption_tax
A1: Date | B1: Gross local VAT | C1: VAT refund autonomy and traders | D1: Total net VAT | E1: Net local sales tax | F1: Gross fuel tax
A2: 35065 | B2: =[1]עקיף!$C6 -> 2195.745 | C2: =-1*[1]עקיף!$D6 -> -1105.54 | D2: =SUM(consumption_tax!B2:C2, import_trade_tax!B2) -> 2419.796 | E2: =[1]עקיף!$I6 -> 52.85 | F2: =[1]עקיף!$K6 -> 313.693
A3: 35096 | B3: =[1]עקיף!$C7 -> 1653.143 | C3: =-1*[1]עקיף!$D7 -> -890.026 | D3: =SUM(consumption_tax!B3:C3, import_trade_tax!B3) -> 1999.59 | E3: =[1]עקיף!$I7 -> 42.954 | F3: =[1]עקיף!$K7 -> 295.983
A4: 35125 | B4: =[1]עקיף!$C8 -> 2036.886 | C4: =-1*[1]עקיף!$D8 -> -855.709 | D4: =SUM(consumption_tax!B4:C4, import_trade_tax!B4) -> 2465.019 | E4: =[1]עקיף!$I8 -> 65.788 | F4: =[1]עקיף!$K8 -> 325.787
A5: 35156 | B5: =[1]עקיף!$C9 -> 1691.719 | C5: =-1*[1]עקיף!$D9 -> -701.956 | D5: =SUM(consumption_tax!B5:C5, import_trade_tax!B5) -> 2330.863 | E5: =[1]עקיף!$I9 -> 18.831 | F5: =[1]עקיף!$K9 -> 322.173
A6: 35186 | B6: =[1]עקיף!$C10 -> 1916.726 | C6: =-1*[1]עקיף!$D10 -> -800.717 | D6: =SUM(consumption_tax!B6:C6, import_trade_tax!B6) -> 2379.655 | E6: =[1]עקיף!$I10 -> 83.942 | F6: =[1]עקיף!$K10 -> 359.873
A7: 35217 | B7: =[1]עקיף!$C11 -> 1649.328 | C7: =-1*[1]עקיף!$D11 -> -784.963 | D7: =SUM(consumption_tax!B7:C7, import_trade_tax!B7) -> 2114.776 | E7: =[1]עקיף!$I11 -> 16.452 | F7: =[1]עקיף!$K11 -> 334.147
A8: 35247 | B8: =[1]עקיף!$C12 -> 2315.517 | C8: =-1*[1]עקיף!$D12 -> -872.002 | D8: =SUM(consumption_tax!B8:C8, import_trade_tax!B8) -> 2742.126 | E8: =[1]עקיף!$I12 -> 101.975 | F8: =[1]עקיף!$K12 -> 373.177
A9: 35278 | B9: =[1]עקיף!$C13 -> 1771.971 | C9: =-1*[1]עקיף!$D13 -> -861.78 | D9: =SUM(consumption_tax!B9:C9, import_trade_tax!B9) -> 2052.112 | E9: =[1]עקיף!$I13 -> 50.08 | F9: =[1]עקיף!$K13 -> 379.707
A10: 35309 | B10: =[1]עקיף!$C14 -> 2308.711 | C10: =-1*[1]עקיף!$D14 -> -787.981 | D10: =SUM(consumption_tax!B10:C10, import_trade_tax!B10) -> 2669.55 | E10: =[1]עקיף!$I14 -> 74.217 | F10: =[1]עקיף!$K14 -> 375.522
A11: 35339 | B11: =[1]עקיף!$C15 -> 1641.973 | C11: =-1*[1]עקיף!$D15 -> -787.485 | D11: =SUM(consumption_tax!B11:C11, import_trade_tax!B11) -> 2183.644 | E11: =[1]עקיף!$I15 -> 101.374 | F11: =[1]עקיף!$K15 -> 360.598
A12: 35370 | B12: =[1]עקיף!$C16 -> 2166.519 | C12: =-1*[1]עקיף!$D16 -> -865.378 | D12: =SUM(consumption_tax!B12:C12, import_trade_tax!B12) -> 2425.009 | E12: =[1]עקיף!$I16 -> 25.339 | F12: =[1]עקיף!$K16 -> 330.95
A13: 35400 | B13: =[1]עקיף!$C17 -> 1631.195 | C13: =-1*[1]עקיף!$D17 -> -686.16 | D13: =SUM(consumption_tax!B13:C13, import_trade_tax!B13) -> 2089.782 | E13: =[1]עקיף!$I17 -> 84.311 | F13: =[1]עקיף!$K17 -> 387.349
... A365: 46113 | B365: =[1]עקיף!$C369 -> 12238 | C365: =-1*[1]עקיף!$D369 -> -3371.6667 | D365: =SUM(consumption_tax!B365:C365, import_trade_tax!B365) -> 14339 | E365: =[1]עקיף!$I369 -> 43 | F365: =[1]עקיף!$K369 -> 2095.3333

Sheet import_trade_tax
A1: Date | B1: Gross import VAT | C1: Net customs | D1: Net import purchase tax | E1: Total import taxes
A2: 35065 | B2: =[1]עקיף!$B6 -> 1329.591 | C2: =[1]עקיף!$F6 -> 92.499 | D2: =[1]עקיף!$G6 -> 610.502 | E2: =SUM(C2:D2) -> 703.001
A3: 35096 | B3: =[1]עקיף!$B7 -> 1236.473 | C3: =[1]עקיף!$F7 -> 91.481 | D3: =[1]עקיף!$G7 -> 545.64 | E3: =SUM(C3:D3) -> 637.121
A4: 35125 | B4: =[1]עקיף!$B8 -> 1283.842 | C4: =[1]עקיף!$F8 -> 107.24 | D4: =[1]עקיף!$G8 -> 619.378 | E4: =SUM(C4:D4) -> 726.618
A5: 35156 | B5: =[1]עקיף!$B9 -> 1341.1 | C5: =[1]עקיף!$F9 -> 79.756 | D5: =[1]עקיף!$G9 -> 525.151 | E5: =SUM(C5:D5) -> 604.907
A6: 35186 | B6: =[1]עקיף!$B10 -> 1263.646 | C6: =[1]עקיף!$F10 -> 91.894 | D6: =[1]עקיף!$G10 -> 623.029 | E6: =SUM(C6:D6) -> 714.923
A7: 35217 | B7: =[1]עקיף!$B11 -> 1250.411 | C7: =[1]עקיף!$F11 -> 87.794 | D7: =[1]עקיף!$G11 -> 615.833 | E7: =SUM(C7:D7) -> 703.627
A8: 35247 | B8: =[1]עקיף!$B12 -> 1298.611 | C8: =[1]עקיף!$F12 -> 86.295 | D8: =[1]עקיף!$G12 -> 516.929 | E8: =SUM(C8:D8) -> 603.224
A9: 35278 | B9: =[1]עקיף!$B13 -> 1141.921 | C9: =[1]עקיף!$F13 -> 84.575 | D9: =[1]עקיף!$G13 -> 530.11 | E9: =SUM(C9:D9) -> 614.685
A10: 35309 | B10: =[1]עקיף!$B14 -> 1148.82 | C10: =[1]עקיף!$F14 -> 83.609 | D10: =[1]עקיף!$G14 -> 538.35 | E10: =SUM(C10:D10) -> 621.959
A11: 35339 | B11: =[1]עקיף!$B15 -> 1329.156 | C11: =[1]עקיף!$F15 -> 90.083 | D11: =[1]עקיף!$G15 -> 622.882 | E11: =SUM(C11:D11) -> 712.965
A12: 35370 | B12: =[1]עקיף!$B16 -> 1123.868 | C12: =[1]עקיף!$F16 -> 77.044 | D12: =[1]עקיף!$G16 -> 534.281 | E12: =SUM(C12:D12) -> 611.325
A13: 35400 | B13: =[1]עקיף!$B17 -> 1144.747 | C13: =[1]עקיף!$F17 -> 87.998 | D13: =[1]עקיף!$G17 -> 671.833 | E13: =SUM(C13:D13) -> 759.831
... A365: 46113 | B365: =[1]עקיף!$B369 -> 5472.6667 | C365: =[1]עקיף!$F369 -> 122 | D365: =[1]עקיף!$G369 -> 1891 | E365: =SUM(C365:D365) -> 2013

Sheet real_estate
A1: Date | B1: Real estate taxation | C1: Property tax | D1: praise tax | E1: Real estate purchase tax | F1: praise tax returns | G1: purchase returns | H1: Apartments sold at an annual rate | I1: Apartment Price Index (1993=100) - Mid-period reviewed
A2: 34700 | I2: =[2]monthly!$AC101 -> 140.3
A3: 34731 | I3: =[2]monthly!$AC102 -> 140.7
A4: 34759 | I4: =[2]monthly!$AC103 -> 141.5
A5: 34790 | I5: =[2]monthly!$AC104 -> 142.7
A6: 34820 | I6: =[2]monthly!$AC105 -> 144.4
A7: 34851 | I7: =[2]monthly!$AC106 -> 145.5
A8: 34881 | I8: =[2]monthly!$AC107 -> 148.7
A9: 34912 | I9: =[2]monthly!$AC108 -> 151.8
A10: 34943 | I10: =[2]monthly!$AC109 -> 151.9
A11: 34973 | I11: =[2]monthly!$AC110 -> 153.5
A12: 35004 | I12: =[2]monthly!$AC111 -> 157.9
A13: 35034 | I13: =[2]monthly!$AC112 -> 162.7
A14: 35065 | B14: ='[1]ישיר מתוקן'!$G6 -> 423290 | C14: ='[1]ישיר מתוקן'!$N6 -> 159430 | D14: ='[1]ישיר מתוקן'!$P6 -> 108675 | E14: ='[1]ישיר מתוקן'!$R6 -> 156272 | F14: =-1*'[1]ישיר מתוקן'!$AK6 -> -16848 | G14: =-1*'[1]ישיר מתוקן'!$AL6 -> -6000 | I14: =[2]monthly!$AC113 -> 164.7
A15: 35096 | B15: ='[1]ישיר מתוקן'!$G7 -> 440678 | C15: ='[1]ישיר מתוקן'!$N7 -> 121792 | D15: ='[1]ישיר מתוקן'!$P7 -> 146495 | E15: ='[1]ישיר מתוקן'!$R7 -> 172882 | F15: =-1*'[1]ישיר מתוקן'!$AK7 -> -5091 | G15: =-1*'[1]ישיר מתוקן'!$AL7 -> -3606 | I15: =[2]monthly!$AC114 -> 164.7
A16: 35125 | B16: ='[1]ישיר מתוקן'!$G8 -> 356479 | C16: ='[1]ישיר מתוקן'!$N8 -> 62541 | D16: ='[1]ישיר מתוקן'!$P8 -> 140702 | E16: ='[1]ישיר מתוקן'!$R8 -> 153513 | F16: =-1*'[1]ישיר מתוקן'!$AK8 -> -11221 | G16: =-1*'[1]ישיר מתוקן'!$AL8 -> -6684 | I16: =[2]monthly!$AC115 -> 167
A17: 35156 | B17: ='[1]ישיר מתוקן'!$G9 -> 305373 | C17: ='[1]ישיר מתוקן'!$N9 -> 79702 | D17: ='[1]ישיר מתוקן'!$P9 -> 95487 | E17: ='[1]ישיר מתוקן'!$R9 -> 133888 | F17: =-1*'[1]ישיר מתוקן'!$AK9 -> -7480 | G17: =-1*'[1]ישיר מתוקן'!$AL9 -> -3768 | I17: =[2]monthly!$AC116 -> 171.8
A18: 35186 | B18: ='[1]ישיר מתוקן'!$G10 -> 323794 | C18: ='[1]ישיר מתוקן'!$N10 -> 61818 | D18: ='[1]ישיר מתוקן'!$P10 -> 124786 | E18: ='[1]ישיר מתוקן'!$R10 -> 139256 | F18: =-1*'[1]ישיר מתוקן'!$AK10 -> -4311 | G18: =-1*'[1]ישיר מתוקן'!$AL10 -> -2868 | I18: =[2]monthly!$AC117 -> 175.3
A19: 35217 | B19: ='[1]ישיר מתוקן'!$G11 -> 312892 | C19: ='[1]ישיר מתוקן'!$N11 -> 58135 | D19: ='[1]ישיר מתוקן'!$P11 -> 100641 | E19: ='[1]ישיר מתוקן'!$R11 -> 155001 | F19: =-1*'[1]ישיר מתוקן'!$AK11 -> -10043 | G19: =-1*'[1]ישיר מתוקן'!$AL11 -> -5532 | I19: =[2]monthly!$AC118 -> 174.6
A20: 35247 | B20: ='[1]ישיר מתוקן'!$G12 -> 302668 | C20: ='[1]ישיר מתוקן'!$N12 -> 76484 | D20: ='[1]ישיר מתוקן'!$P12 -> 92346 | E20: ='[1]ישיר מתוקן'!$R12 -> 135372 | F20: =-1*'[1]ישיר מתוקן'!$AK12 -> -3902 | G20: =-1*'[1]ישיר מתוקן'!$AL12 -> -3644 | I20: =[2]monthly!$AC119 -> 171.6
A21: 35278 | B21: ='[1]ישיר מתוקן'!$G13 -> 286209 | C21: ='[1]ישיר מתוקן'!$N13 -> 62130 | D21: ='[1]ישיר מתוקן'!$P13 -> 96239 | E21: ='[1]ישיר מתוקן'!$R13 -> 130065 | F21: =-1*'[1]ישיר מתוקן'!$AK13 -> -4986 | G21: =-1*'[1]ישיר מתוקן'!$AL13 -> -4643 | I21: =[2]monthly!$AC120 -> 170.8
A22: 35309 | B22: ='[1]ישיר מתוקן'!$G14 -> 228648 | C22: ='[1]ישיר מתוקן'!$N14 -> 55398 | D22: ='[1]ישיר מתוקן'!$P14 -> 60223 | E22: ='[1]ישיר מתוקן'!$R14 -> 113446 | F22: =-1*'[1]ישיר מתוקן'!$AK14 -> -8643 | G22: =-1*'[1]ישיר מתוקן'!$AL14 -> -7721 | I22: =[2]monthly!$AC121 -> 173.5
A23: 35339 | B23: ='[1]ישיר מתוקן'!$G15 -> 212560 | C23: ='[1]ישיר מתוקן'!$N15 -> 64511 | D23: ='[1]ישיר מתוקן'!$P15 -> 52455 | E23: ='[1]ישיר מתוקן'!$R15 -> 96763 | F23: =-1*'[1]ישיר מתוקן'!$AK15 -> -4429 | G23: =-1*'[1]ישיר מתוקן'!$AL15 -> -4215 | I23: =[2]monthly!$AC122 -> 176.4
A24: 35370 | B24: ='[1]ישיר מתוקן'!$G16 -> 236927 | C24: ='[1]ישיר מתוקן'!$N16 -> 69713 | D24: ='[1]ישיר מתוקן'!$P16 -> 70964 | E24: ='[1]ישיר מתוקן'!$R16 -> 97544 | F24: =-1*'[1]ישיר מתוקן'!$AK16 -> -3593 | G24: =-1*'[1]ישיר מתוקן'!$AL16 -> -6813 | I24: =[2]monthly!$AC123 -> 177.1
A25: 35400 | B25: ='[1]ישיר מתוקן'!$G17 -> 305954 | C25: ='[1]ישיר מתוקן'!$N17 -> 89978 | D25: ='[1]ישיר מתוקן'!$P17 -> 97409 | E25: ='[1]ישיר מתוקן'!$R17 -> 119858 | F25: =-1*'[1]ישיר מתוקן'!$AK17 -> -6468 | G25: =-1*'[1]ישיר מתוקן'!$AL17 -> -6333 | I25: =[2]monthly!$AC124 -> 178.4
... A37: 35765 | B37: ='[1]ישיר מתוקן'!$G29 -> 293938 | C37: ='[1]ישיר מתוקן'!$N29 -> 98325 | D37: ='[1]ישיר מתוקן'!$P29 -> 80080 | E37: ='[1]ישיר מתוקן'!$R29 -> 117335 | F37: =-1*'[1]ישיר מתוקן'!$AK29 -> -4354 | G37: =-1*'[1]ישיר מתוקן'!$AL29 -> -3439 | I37: =[2]monthly!$AC136 -> 190.9
A38: 35796 | B38: ='[1]ישיר מתוקן'!$G30 -> 186943 | C38: ='[1]ישיר מתוקן'!$N30 -> 34619 | D38: ='[1]ישיר מתוקן'!$P30 -> 56313 | E38: ='[1]ישיר מתוקן'!$R30 -> 96872 | F38: =-1*'[1]ישיר מתוקן'!$AK30 -> -83 | G38: =-1*'[1]ישיר מתוקן'!$AL30 -> -168 | H38: 19212 | I38: =[2]monthly!$AC137 -> 191.1
A39: 35827 | B39: ='[1]ישיר מתוקן'!$G31 -> 322828 | C39: ='[1]ישיר מתוקן'!$N31 -> 93066 | D39: ='[1]ישיר מתוקן'!$P31 -> 90182 | E39: ='[1]ישיר מתוקן'!$R31 -> 145186 | F39: =-1*'[1]ישיר מתוקן'!$AK31 -> -12534 | G39: =-1*'[1]ישיר מתוקן'!$AL31 -> -8106 | H39: 21600 | I39: =[2]monthly!$AC138 -> 190.1
A40: 35855 | B40: ='[1]ישיר מתוקן'!$G32 -> 362049 | C40: ='[1]ישיר מתוקן'!$N32 -> 141846 | D40: ='[1]ישיר מתוקן'!$P32 -> 96269 | E40: ='[1]ישיר מתוקן'!$R32 -> 126314 | F40: =-1*'[1]ישיר מתוקן'!$AK32 -> -11124 | G40: =-1*'[1]ישיר מתוקן'!$AL32 -> -9762 | H40: 20196 | I40: =[2]monthly!$AC139 -> 191.6
A41: 35886 | B41: ='[1]ישיר מתוקן'!$G33 -> 305373 | C41: ='[1]ישיר מתוקן'!$N33 -> 104061 | D41: ='[1]ישיר מתוקן'!$P33 -> 92562 | E41: ='[1]ישיר מתוקן'!$R33 -> 109538 | F41: =-1*'[1]ישיר מתוקן'!$AK33 -> -5808 | G41: =-1*'[1]ישיר מתוקן'!$AL33 -> -6413 | H41: 18012 | I41: =[2]monthly!$AC140 -> 193.5
A42: 35916 | B42: ='[1]ישיר מתוקן'!$G34 -> 282235 | C42: ='[1]ישיר מתוקן'!$N34 -> 81495 | D42: ='[1]ישיר מתוקן'!$P34 -> 88438 | E42: ='[1]ישיר מתוקן'!$R34 -> 114555 | F42: =-1*'[1]ישיר מתוקן'!$AK34 -> -8228 | G42: =-1*'[1]ישיר מתוקן'!$AL34 -> -6347 | H42: 18888 | I42: =[2]monthly!$AC141 -> 193.4
A43: 35947 | B43: ='[1]ישיר מתוקן'!$G35 -> 225182 | C43: ='[1]ישיר מתוקן'!$N35 -> 68133 | D43: ='[1]ישיר מתוקן'!$P35 -> 63358 | E43: ='[1]ישיר מתוקן'!$R35 -> 100093 | F43: =-1*'[1]ישיר מתוקן'!$AK35 -> -9483 | G43: =-1*'[1]ישיר מתוקן'!$AL35 -> -6124 | H43: 17256 | I43: =[2]monthly!$AC142 -> 190.1
A44: 35977 | B44: ='[1]ישיר מתוקן'!$G36 -> 322205 | C44: ='[1]ישיר מתוקן'!$N36 -> 93910 | D44: ='[1]ישיר מתוקן'!$P36 -> 102383 | E44: ='[1]ישיר מתוקן'!$R36 -> 127552 | F44: =-1*'[1]ישיר מתוקן'!$AK36 -> -9708 | G44: =-1*'[1]ישיר מתוקן'!$AL36 -> -5906 | H44: 18168 | I44: =[2]monthly!$AC143 -> 188.1
A45: 36008 | B45: ='[1]ישיר מתוקן'!$G37 -> 201727 | C45: ='[1]ישיר מתוקן'!$N37 -> 54079 | D45: ='[1]ישיר מתוקן'!$P37 -> 47955 | E45: ='[1]ישיר מתוקן'!$R37 -> 100293 | F45: =-1*'[1]ישיר מתוקן'!$AK37 -> -6277 | G45: =-1*'[1]ישיר מתוקן'!$AL37 -> -3936 | H45: 24612 | I45: =[2]monthly!$AC144 -> 191
A46: 36039 | B46: ='[1]ישיר מתוקן'!$G38 -> 130425 | C46: ='[1]ישיר מתוקן'!$N38 -> 22473 | D46: ='[1]ישיר מתוקן'!$P38 -> 57619 | E46: ='[1]ישיר מתוקן'!$R38 -> 50341 | F46: =-1*'[1]ישיר מתוקן'!$AK38 -> -49 | G46: =-1*'[1]ישיר מתוקן'!$AL38 -> -134 | H46: 19260 | I46: =[2]monthly!$AC145 -> 198.3
A47: 36069 | B47: ='[1]ישיר מתוקן'!$G39 -> 261436 | C47: ='[1]ישיר מתוקן'!$N39 -> 68734 | D47: ='[1]ישיר מתוקן'!$P39 -> 75964 | E47: ='[1]ישיר מתוקן'!$R39 -> 120141 | F47: =-1*'[1]ישיר מתוקן'!$AK39 -> -8254 | G47: =-1*'[1]ישיר מתוקן'!$AL39 -> -4844 | H47: 21420 | I47: =[2]monthly!$AC146 -> 204.4
A48: 36100 | B48: ='[1]ישיר מתוקן'!$G40 -> 405679 | C48: ='[1]ישיר מתוקן'!$N40 -> 149000 | D48: ='[1]ישיר מתוקן'!$P40 -> 101090 | E48: ='[1]ישיר מתוקן'!$R40 -> 159719 | F48: =-1*'[1]ישיר מתוקן'!$AK40 -> -6269 | G48: =-1*'[1]ישיר מתוקן'!$AL40 -> -5306 | H48: 19356 | I48: =[2]monthly!$AC147 -> 204.4
A49: 36130 | B49: ='[1]ישיר מתוקן'!$G41 -> 332107 | C49: ='[1]ישיר מתוקן'!$N41 -> 92851 | D49: ='[1]ישיר מתוקן'!$P41 -> 87415 | E49: ='[1]ישיר מתוקן'!$R41 -> 153624 | F49: =-1*'[1]ישיר מתוקן'!$AK41 -> -14035 | G49: =-1*'[1]ישיר מתוקן'!$AL41 -> -8231 | H49: 19692 | I49: =[2]monthly!$AC148 -> 204.3
... A374: 46023 | B374: ='[1]ישיר מתוקן'!$G366 -> 1863523 | C374: ='[1]ישיר מתוקן'!$N366 -> 1617 | D374: ='[1]ישיר מתוקן'!$P366 -> 730825 | E374: ='[1]ישיר מתוקן'!$R366 -> 1138118 | F374: =-1*'[1]ישיר מתוקן'!$AK366 -> -126400 | G374: =-1*'[1]ישיר מתוקן'!$AL366 -> -58311 | H374: 58609 | I374: =[2]monthly!$AC473 -> 599.6
A375: 46054 | B375: ='[1]ישיר מתוקן'!$G367 -> 2183983 | C375: ='[1]ישיר מתוקן'!$N367 -> 2729 | D375: ='[1]ישיר מתוקן'!$P367 -> 777969 | E375: ='[1]ישיר מתוקן'!$R367 -> 1407911 | F375: =-1*'[1]ישיר מתוקן'!$AK367 -> -58017 | G375: =-1*'[1]ישיר מתוקן'!$AL367 -> -52032 | H375: 58610
...

Sheet real_activity
A1: Date | B1: cons_trust | C1: madad meshulav | D1: madad_cc_purchases_sa | E1: madad_pedio | F1: madad_yetzur_industrial | G1: Oil
A2: 34700 | C2: 36.02323 | E2: 47.048071 | F2: 43.63031 | G2: =[2]monthly!$D101 -> 18.039524
A3: 34731 | C3: 36.22936 | E3: 48.042747 | F3: 43.8588 | G3: =[2]monthly!$D102 -> 18.57
A4: 34759 | C4: 36.44757 | E4: 48.765421 | F4: 43.66354 | G4: =[2]monthly!$D103 -> 18.53913
A5: 34790 | C5: 36.78331 | E5: 48.433906 | F5: 44.53219 | G5: =[2]monthly!$D104 -> 19.896316
A6: 34820 | C6: 37.03361 | E6: 48.35516 | F6: 45.48883 | G6: =[2]monthly!$D105 -> 19.741818
A7: 34851 | C7: 37.25403 | E7: 48.14714 | F7: 44.36347 | G7: =[2]monthly!$D106 -> 18.445909
A8: 34881 | C8: 37.449 | E8: 48.80995 | F8: 45.74745 | G8: =[2]monthly!$D107 -> 17.3255
A9: 34912 | C9: 37.61636 | E9: 49.985692 | F9: 46.12689 | G9: =[2]monthly!$D108 -> 18.02087
A10: 34943 | C10: 37.77913 | E10: 49.795656 | F10: 45.65196 | G10: =[2]monthly!$D109 -> 18.2255
A11: 34973 | C11: 37.93102 | E11: 50.802585 | F11: 45.96316 | G11: =[2]monthly!$D110 -> 17.433182
A12: 35004 | C12: 38.0852 | E12: 51.288368 | F12: 45.92934 | G12: =[2]monthly!$D111 -> 17.9925
A13: 35034 | C13: 38.245 | E13: 54.993203 | F13: 46.91861 | G13: =[2]monthly!$D112 -> 19.0265
A14: 35065 | C14: 38.36861 | E14: 52.064805 | F14: 46.62268 | G14: =[2]monthly!$D113 -> 18.854545
A15: 35096 | C15: 38.37893 | D15: 22.66118 | E15: 51.949355 | F15: 46.82253 | G15: =[2]monthly!$D114 -> 19.0935
A16: 35125 | C16: 38.32984 | D16: 22.78054 | E16: 52.238659 | F16: 47.3226 | G16: =[2]monthly!$D115 -> 21.332381
A17: 35156 | C17: 38.27404 | D17: 22.83932 | E17: 52.380951 | F17: 47.3257 | G17: =[2]monthly!$D116 -> 23.497143
A18: 35186 | C18: 38.25835 | D18: 23.26217 | E18: 53.41345 | F18: 46.76416 | G18: =[2]monthly!$D117 -> 21.165455
A19: 35217 | C19: 38.29493 | D19: 22.98347 | E19: 52.743007 | F19: 47.68579 | G19: =[2]monthly!$D118 -> 20.4235
A20: 35247 | C20: 38.37307 | D20: 23.04468 | E20: 52.891319 | F20: 46.40966 | G20: =[2]monthly!$D119 -> 21.302273
A21: 35278 | C21: 38.40751 | D21: 22.60813 | E21: 51.845425 | F21: 47.45461 | G21: =[2]monthly!$D120 -> 21.903182
A22: 35309 | C22: 38.40043 | D22: 23.05225 | E22: 52.930398 | F22: 48.11083 | G22: =[2]monthly!$D121 -> 23.9715
A23: 35339 | C23: 38.36188 | D23: 22.96747 | E23: 52.725548 | F23: 47.29437 | G23: =[2]monthly!$D122 -> 24.87913
A24: 35370 | C24: 38.3806 | D24: 22.72123 | E24: 52.132931 | F24: 46.9677 | G24: =[2]monthly!$D123 -> 23.705
A25: 35400 | C25: 38.53757 | D25: 22.52757 | E25: 51.666554 | F25: 47.06549 | G25: =[2]monthly!$D124 -> 25.228571
A26: 35431 | C26: 38.63802 | D26: 23.42988 | E26: 53.8951 | F26: 47.99719 | G26: =[2]monthly!$D125 -> 25.131818
... A88: 37316 | C88: 45.42859 | D88: 28.57354 | E88: 67.366873 | F88: 52.0828 | G88: =[2]monthly!$D187 -> 24.531
A89: 37347 | B89: =[7]monthly!$CH188 -> 100 | C89: 45.53598 | D89: 29.17511 | E89: 68.594967 | F89: 52.45974 | G89: =[2]monthly!$D188 -> 26.179091
A90: 37377 | B90: =[7]monthly!$CH189 -> 97.8 | C90: 45.60008 | D90: 29.46036 | E90: 68.787685 | F90: 51.92006 | G90: =[2]monthly!$D189 -> 27.041364
A91: 37408 | B91: =[7]monthly!$CH190 -> 95.6 | C91: 45.79526 | D91: 29.8279 | E91: 69.35804 | F91: 51.95757 | G91: =[2]monthly!$D190 -> 25.5185
A92: 37438 | B92: =[7]monthly!$CH191 -> 94.6 | C92: 45.99349 | D92: 30.49605 | E92: 67.348812 | F92: 51.32919 | G92: =[2]monthly!$D191 -> 26.96619
A93: 37469 | B93: =[7]monthly!$CH192 -> 89.4 | C93: 46.18412 | D93: 29.99272 | E93: 67.980952 | F93: 51.41789 | G93: =[2]monthly!$D192 -> 28.385
A94: 37500 | B94: =[7]monthly!$CH193 -> 99.6 | C94: 46.26637 | D94: 29.79457 | E94: 68.409411 | F94: 51.74475 | G94: =[2]monthly!$D193 -> 29.6635
A95: 37530 | B95: =[7]monthly!$CH194 -> 89.8 | C95: 46.34809 | D95: 30.2165 | E95: 67.671422 | F95: 51.22981 | G95: =[2]monthly!$D194 -> 28.836522
A96: 37561 | B96: =[7]monthly!$CH195 -> 91 | C96: 46.35832 | D96: 30.00421 | E96: 67.470405 | F96: 50.92849 | G96: =[2]monthly!$D195 -> 26.352105
A97: 37591 | B97: =[7]monthly!$CH196 -> 93 | C97: 46.54187 | D97: 29.50359 | E97: 69.746608 | F97: 51.8994 | G97: =[2]monthly!$D196 -> 29.460952
A98: 37622 | B98: =[7]monthly!$CH197 -> 95 | C98: 46.60886 | D98: 32.65577 | E98: 67.028519 | F98: 51.88104 | G98: =[2]monthly!$D197 -> 32.947143
A99: 37653 | B99: =[7]monthly!$CH198 -> 97 | C99: 46.63329 | D99: 32.67193 | E99: 66.114403 | F99: 51.63769 | G99: =[2]monthly!$D198 -> 35.828421
A100: 37681 | B100: =[7]monthly!$CH199 -> 102.2 | C100: 46.5864 | D100: 32.64498 | E100: 64.822618 | F100: 51.06438 | G100: =[2]monthly!$D199 -> 33.513333
... A361: 45627 | B361: =[7]monthly!$CH460 -> 123.9 | C361: 99.56221 | D361: 125.6964 | E361: 188.62567 | F361: 103.3226 | G361: =[2]monthly!$D460 -> 70.118095
...

Sheet labor
A1: Date | B1: real salary | C1: salaried jobs | D1: unemployment rate | E1: participation rate | F1: employment rate
A2: 34700 | B2: =[3]monthly!$M102 -> 7427.314 | C2: =[3]monthly!$R102 -> 2021.1302
A3: 34731 | B3: =[3]monthly!$M103 -> 7544.8911 | C3: =[3]monthly!$R103 -> 2016.674
A4: 34759 | B4: =[3]monthly!$M104 -> 7546.6177 | C4: =[3]monthly!$R104 -> 2048.5051
A5: 34790 | B5: =[3]monthly!$M105 -> 7457.2373 | C5: =[3]monthly!$R105 -> 2059.9927
A6: 34820 | B6: =[3]monthly!$M106 -> 7634.605 | C6: =[3]monthly!$R106 -> 2066.8035
A7: 34851 | B7: =[3]monthly!$M107 -> 7666.6138 | C7: =[3]monthly!$R107 -> 2072.4465
A8: 34881 | B8: =[3]monthly!$M108 -> 7711.3384 | C8: =[3]monthly!$R108 -> 2083.4309
A9: 34912 | B9: =[3]monthly!$M109 -> 7663.5098 | C9: =[3]monthly!$R109 -> 2090.7678
A10: 34943 | B10: =[3]monthly!$M110 -> 7623.0068 | C10: =[3]monthly!$R110 -> 2100.9612
A11: 34973 | B11: =[3]monthly!$M111 -> 7583.4497 | C11: =[3]monthly!$R111 -> 2105.4734
A12: 35004 | B12: =[3]monthly!$M112 -> 7649.2476 | C12: =[3]monthly!$R112 -> 2108.093
A13: 35034 | B13: =[3]monthly!$M113 -> 7579.8232 | C13: =[3]monthly!$R113 -> 2113.3997
... A205: 40878 | B205: =[3]monthly!$M305 -> 8630.2305 | C205: =[3]monthly!$R305 -> 3219.5471
A206: 40909 | B206: =[3]monthly!$M306 -> 8502.4082 | C206: =[3]monthly!$R306 -> 3246.7 | D206: =[3]monthly!AY306 -> 0.057187235 | E206: =[3]monthly!AZ306 -> 0.77899079 | F206: =[3]monthly!BA306 -> 0.73444246
A207: 40940 | B207: =[3]monthly!$M307 -> 8615.858 | C207: =[3]monthly!$R307 -> 3253 | D207: =[3]monthly!AY307 -> 0.059773431 | E207: =[3]monthly!AZ307 -> 0.78072898 | F207: =[3]monthly!BA307 -> 0.73406213
A208: 40969 | B208: =[3]monthly!$M308 -> 8591.437 | C208: =[3]monthly!$R308 -> 3268 | D208: =[3]monthly!AY308 -> 0.060282575 | E208: =[3]monthly!AZ308 -> 0.78525641 | F208: =[3]monthly!BA308 -> 0.73791913
A209: 41000 | B209: =[3]monthly!$M309 -> 8569.4524 | C209: =[3]monthly!$R309 -> 3272.3999 | D209: =[3]monthly!AY309 -> 0.059340353 | E209: =[3]monthly!AZ309 -> 0.78593741 | F209: =[3]monthly!BA309 -> 0.73929961
A210: 41030 | B210: =[3]monthly!$M310 -> 8663.001 | C210: =[3]monthly!$R310 -> 3275.3999 | D210: =[3]monthly!AY310 -> 0.061226615 | E210: =[3]monthly!AZ310 -> 0.78768078 | F210: =[3]monthly!BA310 -> 0.73945376
A211: 41061 | B211: =[3]monthly!$M311 -> 8668.4413 | C211: =[3]monthly!$R311 -> 3270 | D211: =[3]monthly!AY311 -> 0.059680321 | E211: =[3]monthly!AZ311 -> 0.79011536 | F211: =[3]monthly!BA311 -> 0.74296102
A212: 41091 | B212: =[3]monthly!$M312 -> 8631.3605 | C212: =[3]monthly!$R312 -> 3289.6001 | D212: =[3]monthly!AY312 -> 0.058193701 | E212: =[3]monthly!AZ312 -> 0.78722531 | F212: =[3]monthly!BA312 -> 0.74144112
A213: 41122 | B213: =[3]monthly!$M313 -> 8582.5051 | C213: =[3]monthly!$R313 -> 3295.2 | D213: =[3]monthly!AY313 -> 0.056901603 | E213: =[3]monthly!AZ313 -> 0.79480085 | F213: =[3]monthly!BA313 -> 0.74957541
A214: 41153 | B214: =[3]monthly!$M314 -> 8621.9047 | C214: =[3]monthly!$R314 -> 3290.8 | D214: =[3]monthly!AY314 -> 0.058503637 | E214: =[3]monthly!AZ314 -> 0.78877626 | F214: =[3]monthly!BA314 -> 0.74262998
A215: 41183 | B215: =[3]monthly!$M315 -> 8660.7395 | C215: =[3]monthly!$R315 -> 3301.3999 | D215: =[3]monthly!AY315 -> 0.060629052 | E215: =[3]monthly!AZ315 -> 0.79003869 | F215: =[3]monthly!BA315 -> 0.74213939
A216: 41214 | B216: =[3]monthly!$M316 -> 8701.2854 | C216: =[3]monthly!$R316 -> 3298.8 | D216: =[3]monthly!AY316 -> 0.05820326 | E216: =[3]monthly!AZ316 -> 0.78583694 | F216: =[3]monthly!BA316 -> 0.74009867
A217: 41244 | B217: =[3]monthly!$M317 -> 8759.6367 | C217: =[3]monthly!$R317 -> 3309.8999 | D217: =[3]monthly!AY317 -> 0.057139883 | E217: =[3]monthly!AZ317 -> 0.78340989 | F217: =[3]monthly!BA317 -> 0.73867312
... A375: 46054 | B375: =[3]monthly!$M475 -> 0 | C375: =[3]monthly!$R475 -> 0 | D375: =[3]monthly!AY475 -> 0.02333719 | E375: =[3]monthly!AZ475 -> 0.81210468 | F375: =[3]monthly!BA475 -> 0.79315244
A376: 46082 | B376: =[3]monthly!$M476 -> 0 | C376: =[3]monthly!$R476 -> 0
A377: 46113 | B377: =[3]monthly!$M477 -> 0 | C377: =[3]monthly!$R477 -> 0

Sheet capital_markets
A1: Date | B1: TA35 | C1: TA125 | D1: Nasdaq | E1: sp500
A2: 34700 | B2: =[4]monthly!$D101 -> 165.50652 | C2: =[4]monthly!$E101 -> 163.97826 | D2: =[4]monthly!$F101 -> 758.01238 | E2: =[4]monthly!$G101 -> 465.25
A3: 34731 | B3: =[4]monthly!$D102 -> 160.887 | C3: =[4]monthly!$E102 -> 161.739 | D3: =[4]monthly!$F102 -> 784.24368 | E3: =[4]monthly!$G102 -> 481.92474
A4: 34759 | B4: =[4]monthly!$D103 -> 160.5081 | C4: =[4]monthly!$E103 -> 159.40048 | D4: =[4]monthly!$F103 -> 807.16217 | E4: =[4]monthly!$G103 -> 493.15304
A5: 34790 | B5: =[4]monthly!$D104 -> 166.3595 | C5: =[4]monthly!$E104 -> 164.7245 | D5: =[4]monthly!$F104 -> 825.33842 | E5: =[4]monthly!$G104 -> 507.90579
A6: 34820 | B6: =[4]monthly!$D105 -> 180.16381 | C6: =[4]monthly!$E105 -> 176.9481 | D6: =[4]monthly!$F105 -> 859.77045 | E6: =[4]monthly!$G105 -> 523.81364
A7: 34851 | B7: =[4]monthly!$D106 -> 190.041 | C7: =[4]monthly!$E106 -> 188.3285 | D7: =[4]monthly!$F106 -> 906.03545 | E7: =[4]monthly!$G106 -> 539.35409
A8: 34881 | B8: =[4]monthly!$D107 -> 191.66227 | C8: =[4]monthly!$E107 -> 189.12182 | D8: =[4]monthly!$F107 -> 979.364 | E8: =[4]monthly!$G107 -> 557.3665
A9: 34912 | B9: =[4]monthly!$D108 -> 203.87955 | C9: =[4]monthly!$E108 -> 201.32591 | D9: =[4]monthly!$F108 -> 1009.5861 | E9: =[4]monthly!$G108 -> 559.11
A10: 34943 | B10: =[4]monthly!$D109 -> 209.76765 | C10: =[4]monthly!$E109 -> 206.19412 | D10: =[4]monthly!$F109 -> 1051 | E10: =[4]monthly!$G109 -> 578.7655
A11: 34973 | B11: =[4]monthly!$D110 -> 198.53706 | C11: =[4]monthly!$E110 -> 194.45412 | D11: =[4]monthly!$F110 -> 1022.1482 | E11: =[4]monthly!$G110 -> 582.91818
A12: 35004 | B12: =[4]monthly!$D111 -> 195.405 | C12: =[4]monthly!$E111 -> 189.73864 | D12: =[4]monthly!$F111 -> 1046.6367 | E12: =[4]monthly!$G111 -> 595.53238
A13: 35034 | B13: =[4]monthly!$D112 -> 210.60381 | C13: =[4]monthly!$E112 -> 203.42048 | D13: =[4]monthly!$F112 -> 1047.035 | E13: =[4]monthly!$G112 -> 614.571
... A361: 45627 | B361: =[4]monthly!$D460 -> 2354.1783 | C361: =[4]monthly!$E460 -> 2392.9987 | D361: =[4]monthly!$F460 -> 19734.564 | E361: =[4]monthly!$G460 -> 6010.9086

Sheet FX_liqudity
A1: Date | B1: Reer | C1: Dollar | D1: Foreign exchange reserves (millions of dollars)
A2: 34700 | C2: =[5]monthly!$D101 -> 3.0117143 | D2: =[6]monthly!$BJ101 -> 7655.8463
A3: 34731 | C3: =[5]monthly!$D102 -> 3.00955 | D3: =[6]monthly!$BJ102 -> 8618.6176
A4: 34759 | C4: =[5]monthly!$D103 -> 2.9761429 | D4: =[6]monthly!$BJ103 -> 9091.1186
A5: 34790 | C5: =[5]monthly!$D104 -> 2.9589412 | D5: =[6]monthly!$BJ104 -> 9656.7218
A6: 34820 | C6: =[5]monthly!$D105 -> 3.0042381 | D6: =[6]monthly!$BJ105 -> 9759.9675
A7: 34851 | C7: =[5]monthly!$D106 -> 2.981 | D7: =[6]monthly!$BJ106 -> 8931.5008
A8: 34881 | C8: =[5]monthly!$D107 -> 2.9552857 | D8: =[6]monthly!$BJ107 -> 9076.1771
A9: 34912 | C9: =[5]monthly!$D108 -> 3.0307826 | D9: =[6]monthly!$BJ108 -> 8273.9323
A10: 34943 | C10: =[5]monthly!$D109 -> 3.0355789 | D10: =[6]monthly!$BJ109 -> 8989.8373
A11: 34973 | C11: =[5]monthly!$D110 -> 3.0102778 | D11: =[6]monthly!$BJ110 -> 8529.6768
A12: 35004 | C12: =[5]monthly!$D111 -> 3.042 | D12: =[6]monthly!$BJ111 -> 8409.2189
A13: 35034 | C13: =[5]monthly!$D112 -> 3.1197368 | D13: =[6]monthly!$BJ112 -> 8307.3915
... A55: 36312 | C55: =[5]monthly!$D154 -> 4.0892273 | D55: =[6]monthly!$BJ154 -> 22018.611
A56: 36342 | B56: 91.93878 | C56: =[5]monthly!$D155 -> 4.096619 | D56: =[6]monthly!$BJ155 -> 22234.446
A57: 36373 | B57: 95.246873 | C57: =[5]monthly!$D156 -> 4.2025909 | D57: =[6]monthly!$BJ156 -> 21878.765
A58: 36404 | B58: 96.066598 | C58: =[5]monthly!$D157 -> 4.2467 | D58: =[6]monthly!$BJ157 -> 21944.788
A59: 36434 | B59: 96.873641 | C59: =[5]monthly!$D158 -> 4.2640476 | D59: =[6]monthly!$BJ158 -> 21781.095
A60: 36465 | B60: 94.965279 | C60: =[5]monthly!$D159 -> 4.2262273 | D60: =[6]monthly!$BJ159 -> 21385.765
A61: 36495 | B61: 93.692957 | C61: =[5]monthly!$D160 -> 4.1928182 | D61: =[6]monthly!$BJ160 -> 22605.129
A62: 36526 | B62: 92.514743 | C62: =[5]monthly!$D161 -> 4.1048571 | D62: =[6]monthly!$BJ161 -> 22090.379
A63: 36557 | B63: 90.642963 | C63: =[5]monthly!$D162 -> 4.0535714 | D63: =[6]monthly!$BJ162 -> 22063.018
A64: 36586 | B64: 89.557538 | C64: =[5]monthly!$D163 -> 4.0041429 | D64: =[6]monthly!$BJ163 -> 22765.087
A65: 36617 | B65: 89.581088 | C65: =[5]monthly!$D164 -> 4.0402667 | D65: =[6]monthly!$BJ164 -> 22301.979
A66: 36647 | B66: 88.793741 | C66: =[5]monthly!$D165 -> 4.14555 | D66: =[6]monthly!$BJ165 -> 22264.061
A67: 36678 | B67: 89.763377 | C67: =[5]monthly!$D166 -> 4.1069048 | D67: =[6]monthly!$BJ166 -> 22273.72
... A376: 46082 | B376: 76.985034 | C376: =[5]monthly!$D475 -> 3.1156 | D376: =[6]monthly!$BJ475 -> 224845
A377: 46113 | C377: =[5]monthly!$D476 -> 3.01525 | D377: =[6]monthly!$BJ476 -> 231130

Sheet target
A1: Date | B1: GDP
A2: =[7]quarterly!$B37 -> 34759 | B2: =[7]quarterly!$X37 -> 142787.6
A3: =[7]quarterly!$B38 -> 34851 | B3: =[7]quarterly!$X38 -> 145755.5
A4: =[7]quarterly!$B39 -> 34943 | B4: =[7]quarterly!$X39 -> 147479.1
A5: =[7]quarterly!$B40 -> 35034 | B5: =[7]quarterly!$X40 -> 148423.6
A6: =[7]quarterly!$B41 -> 35125 | B6: =[7]quarterly!$X41 -> 150162.2
A7: =[7]quarterly!$B42 -> 35217 | B7: =[7]quarterly!$X42 -> 152955.2
A8: =[7]quarterly!$B43 -> 35309 | B8: =[7]quarterly!$X43 -> 155037.9
A9: =[7]quarterly!$B44 -> 35400 | B9: =[7]quarterly!$X44 -> 157475.1
A10: =[7]quarterly!$B45 -> 35490 | B10: =[7]quarterly!$X45 -> 159323
A11: =[7]quarterly!$B46 -> 35582 | B11: =[7]quarterly!$X46 -> 159397.2
A12: =[7]quarterly!$B47 -> 35674 | B12: =[7]quarterly!$X47 -> 159549.4
A13: =[7]quarterly!$B48 -> 35765 | B13: =[7]quarterly!$X48 -> 162430.4
... A125: =[7]quarterly!$B160 -> 45992 | B125: =[7]quarterly!$X160 -> 441135.9

Sheet adjusters
A1: Date | B1: VAT_rate | C1: CPI
A2: 34700 | B2: 0.17 | C2: =[2]monthly!$G101 -> 47.154618
A3: 34731 | B3: 0.17 | C3: =[2]monthly!$G102 -> 47.233274
A4: 34759 | B4: 0.17 | C4: =[2]monthly!$G103 -> 47.193946
A5: 34790 | B5: 0.17 | C5: =[2]monthly!$G104 -> 47.626557
A6: 34820 | B6: 0.17 | C6: =[2]monthly!$G105 -> 48.098497
A7: 34851 | B7: 0.17 | C7: =[2]monthly!$G106 -> 48.25581
A8: 34881 | B8: 0.17 | C8: =[2]monthly!$G107 -> 48.373795
A9: 34912 | B9: 0.17 | C9: =[2]monthly!$G108 -> 48.963719
A10: 34943 | B10: 0.17 | C10: =[2]monthly!$G109 -> 49.435658
A11: 34973 | B11: 0.17 | C11: =[2]monthly!$G110 -> 49.946926
A12: 35004 | B12: 0.17 | C12: =[2]monthly!$G111 -> 50.300881
A13: 35034 | B13: 0.17 | C13: =[2]monthly!$G112 -> 50.890805
... A376: 46082 | B376: 0.18 | C376: =[2]monthly!$G475 -> 103.9
A377: 46113 | B377: 0.18
